Workbook
Name ab_cat: Absences!$D$4:$D$101
Name ab_mois: Absences!$M$4:$X$101
Name ab_perim: Absences!$K$4:$K$101
Name ab_statut: Absences!$H$4:$H$101
Name ab_total: Absences!$Y$4:$Y$101
Name cd_date: Candidatures!$C$4:$C$13
Name cl_alerte: Collaborateurs!$N$4:$N$33
Name cl_bur: Collaborateurs!$E$4:$E$33
Name cl_dep: Collaborateurs!$D$4:$D$33
Name cl_emb: Collaborateurs!$F$4:$F$33
Name cl_mat: Collaborateurs!$A$4:$A$33
Name cl_perim: Collaborateurs!$H$4:$H$33
Name cl_present: Collaborateurs!$I$4:$I$33
Name cl_sortie: Collaborateurs!$G$4:$G$33
Name cl_type: Collaborateurs!$K$4:$K$33
Name ct_cle: Contrats!$H$4:$H$58
Name ct_deb: Contrats!$E$4:$E$58
Name ct_fin: Contrats!$F$4:$F$58
Name ct_mat: Contrats!$B$4:$B$58
Name ct_type: Contrats!$C$4:$C$58
Name DateSit: 'Tableau de bord'!$D$4
Name ev_date: 'Étapes recrutement'!$F$4:$F$39
Name ev_etape: 'Étapes recrutement'!$D$4:$D$39
Name ev_offre: 'Étapes recrutement'!$C$4:$C$39
Name ev_res: 'Étapes recrutement'!$G$4:$G$39
Name FiltreBur: 'Tableau de bord'!$D$6
Name FiltreDep: 'Tableau de bord'!$D$5
Name ListeBur: Paramètres!$F$4:$F$7
Name ListeDep: Paramètres!$E$4:$E$12
Name NivEchu: Paramètres!$I$4
Name NivPreparer: Paramètres!$I$6
Name NivRas: Paramètres!$I$8
Name NivSans: Paramètres!$I$9
Name NivSurveiller: Paramètres!$I$7
Name NivUrgent: Paramètres!$I$5
Name SeuilPreparer: Paramètres!$B$5
Name SeuilSurveiller: Paramètres!$B$6
Name SeuilUrgent: Paramètres!$B$4
Name st_perim: Stagiaires!$K$4:$K$9
Name st_statut: Stagiaires!$L$4:$L$9

Sheet Lisez-moi
B1: NURU HR Digital Portfolio – classeur d'analyse RH
B2: Données fictives – Portfolio personnel, non officiel de Nuru
B4: Objet
B5: Tableau de bord RH manipulable : effectifs, contrats et échéances, absences, stagiaires et recrutement, calculés à partir des données fictives du projet (dossier data/raw).
B6: Comment l'utiliser
B7: 1. Ouvrez la feuille « Tableau de bord ».
B8: 2. Modifiez les cellules jaunes : date de situation (année 2026), département, bureau.
B9: 3. Les tuiles, tableaux et graphiques se recalculent. Les feuilles de données ont des filtres (flèches des en-têtes) pour explorer le détail, par exemple les contrats « Urgent ».
B10: 4. Si les valeurs n'apparaissent pas, cliquez sur « Activer la modification » (mode protégé), puis appuyez sur F9.
B11: Feuilles
B12: Tableau de bord : indicateurs, registre mensuel, graphiques.
B13: Paramètres : seuils d'alerte des contrats (modifiables) et listes de référence.
... B25: Généré par dashboard/generer_classeur_excel.py le 15/10/2026. Ne pas modifier les données à la main : relancer le script après la chaîne de traitement.

Sheet Tableau de bord
B1: Tableau de bord RH – classeur d'analyse
B2: Données fictives – Portfolio personnel, non officiel de Nuru
B4: Date de situation | D4: 46326 | F4: Modifiez les cellules jaunes : tous les indicateurs, tableaux et graphiques se recalculent. Date de situation : une date de l'année 2026. Le recrutement n'est pas filtré par département ni par bureau.
B5: Département | D5: Tous
B6: Bureau | D6: Tous
B8: Effectif actif | D8: Part de CDD | F8: CDD à échéance ≤ 30 jours | H8: Contrats échus
B9: =COUNTIFS(cl_perim,1,cl_present,1) -> 27 | D9: =IF(COUNTIFS(cl_perim,1,cl_present,1)=0,0,COUNTIFS(cl_perim,1,cl_present,1,cl_type,"CDD")/COUNTIFS(cl_perim,1,cl_present,1)) -> 0.25925926 | F9: =COUNTIFS(cl_perim,1,cl_alerte,NivUrgent) -> 3 | H9: =COUNTIFS(cl_perim,1,cl_alerte,NivEchu) -> 0
B10: collaborateurs en poste | D10: des collaborateurs en poste | F10: dossier de fin de CDD à préparer | H10: à régulariser
B12: Jours d'absence réalisés | D12: Taux d'absentéisme | F12: Stagiaires en cours | H12: Demandes de congé en attente
B13: =G46 -> 632 | D13: =IF(H46=0,0,G46/H46) -> 0.10514058 | F13: =COUNTIFS(st_perim,1,st_statut,"En cours") -> 2 | H13: =COUNTIFS(ab_perim,1,ab_statut,"En attente") -> 1
B14: jours ouvrables depuis le 1er janvier | D14: jours d'absence / jours ouvrables × effectif | F14: à la date de situation | H14: à traiter par le responsable
B16: Entrées depuis le 1er janvier | D16: Sorties depuis le 1er janvier | F16: Taux de rotation | H16: Candidatures reçues
B17: =D46 -> 4 | D17: =E46 -> 3 | F17: =IF(AVERAGE(F34:F45)=0,0,E46/AVERAGE(F34:F45)) -> 0.10830325 | H17: =COUNTIFS(cd_date,"<="&DateSit) -> 10
B18: embauches | D18: départs | F18: sorties / effectif moyen de fin de mois | H18: toutes offres, sans filtre
B21: Effectif en poste par département et type de contrat (filtre Bureau) | G21: Échéances des contrats
B22: Département | C22: CDI | D22: CDD | E22: Total | G22: Niveau d'alerte | I22: Contrats
B23: Commercial et service client | C23: =COUNTIFS(cl_dep,$B23,cl_present,1,cl_type,"CDI",cl_bur,IF(FiltreBur="Tous","*",FiltreBur)) -> 3 | D23: =COUNTIFS(cl_dep,$B23,cl_present,1,cl_type,"CDD",cl_bur,IF(FiltreBur="Tous","*",FiltreBur)) -> 2 | E23: =C23+D23 -> 5 | G23: =Paramètres!$I$4 -> Échu, à régulariser | I23: =COUNTIFS(cl_perim,1,cl_alerte,G23) -> 0
B24: Direction | C24: =COUNTIFS(cl_dep,$B24,cl_present,1,cl_type,"CDI",cl_bur,IF(FiltreBur="Tous","*",FiltreBur)) -> 2 | D24: =COUNTIFS(cl_dep,$B24,cl_present,1,cl_type,"CDD",cl_bur,IF(FiltreBur="Tous","*",FiltreBur)) -> 0 | E24: =C24+D24 -> 2 | G24: =Paramètres!$I$5 -> Urgent (≤ 30 jours) | I24: =COUNTIFS(cl_perim,1,cl_alerte,G24) -> 3
B25: Finance | C25: =COUNTIFS(cl_dep,$B25,cl_present,1,cl_type,"CDI",cl_bur,IF(FiltreBur="Tous","*",FiltreBur)) -> 2 | D25: =COUNTIFS(cl_dep,$B25,cl_present,1,cl_type,"CDD",cl_bur,IF(FiltreBur="Tous","*",FiltreBur)) -> 1 | E25: =C25+D25 -> 3 | G25: =Paramètres!$I$6 -> À préparer (31 à 60 jours) | I25: =COUNTIFS(cl_perim,1,cl_alerte,G25) -> 0
B26: Informatique | C26: =COUNTIFS(cl_dep,$B26,cl_present,1,cl_type,"CDI",cl_bur,IF(FiltreBur="Tous","*",FiltreBur)) -> 1 | D26: =COUNTIFS(cl_dep,$B26,cl_present,1,cl_type,"CDD",cl_bur,IF(FiltreBur="Tous","*",FiltreBur)) -> 0 | E26: =C26+D26 -> 1 | G26: =Paramètres!$I$7 -> À surveiller (61 à 90 jours) | I26: =COUNTIFS(cl_perim,1,cl_alerte,G26) -> 1
B27: Logistique | C27: =COUNTIFS(cl_dep,$B27,cl_present,1,cl_type,"CDI",cl_bur,IF(FiltreBur="Tous","*",FiltreBur)) -> 5 | D27: =COUNTIFS(cl_dep,$B27,cl_present,1,cl_type,"CDD",cl_bur,IF(FiltreBur="Tous","*",FiltreBur)) -> 1 | E27: =C27+D27 -> 6 | G27: =Paramètres!$I$8 -> RAS (> 90 jours) | I27: =COUNTIFS(cl_perim,1,cl_alerte,G27) -> 3
B28: Opérations techniques | C28: =COUNTIFS(cl_dep,$B28,cl_present,1,cl_type,"CDI",cl_bur,IF(FiltreBur="Tous","*",FiltreBur)) -> 5 | D28: =COUNTIFS(cl_dep,$B28,cl_present,1,cl_type,"CDD",cl_bur,IF(FiltreBur="Tous","*",FiltreBur)) -> 2 | E28: =C28+D28 -> 7 | G28: =Paramètres!$I$9 -> Sans échéance (CDI) | I28: =COUNTIFS(cl_perim,1,cl_alerte,G28) -> 20
B29: Ressources humaines | C29: =COUNTIFS(cl_dep,$B29,cl_present,1,cl_type,"CDI",cl_bur,IF(FiltreBur="Tous","*",FiltreBur)) -> 1 | D29: =COUNTIFS(cl_dep,$B29,cl_present,1,cl_type,"CDD",cl_bur,IF(FiltreBur="Tous","*",FiltreBur)) -> 1 | E29: =C29+D29 -> 2
B30: Services généraux | C30: =COUNTIFS(cl_dep,$B30,cl_present,1,cl_type,"CDI",cl_bur,IF(FiltreBur="Tous","*",FiltreBur)) -> 1 | D30: =COUNTIFS(cl_dep,$B30,cl_present,1,cl_type,"CDD",cl_bur,IF(FiltreBur="Tous","*",FiltreBur)) -> 0 | E30: =C30+D30 -> 1 | G30: Détail et filtres : feuille « Collaborateurs », colonne « Niveau d'alerte ».
B31: Total | C31: =SUM(C23:C30) -> 20 | D31: =SUM(D23:D30) -> 7 | E31: =SUM(E23:E30) -> 27
B32: Registre mensuel 2026 : effectifs et absentéisme (filtres appliqués)
B33: Mois | C33: Effectif début | D33: Entrées | E33: Sorties | F33: Effectif fin | G33: Jours d'absence | H33: Jours ouvrables × effectif | I33: Taux d'absentéisme
B34: =DATE(YEAR(DateSit),1,1) -> 46023 | C34: =IF($B34>DateSit,"",COUNTIFS(cl_perim,1,cl_emb,"<="&($B34-1))-COUNTIFS(cl_perim,1,cl_emb,"<="&($B34-1),cl_sortie,"<="&($B34-1))) -> 26 | D34: =IF($B34>DateSit,"",COUNTIFS(cl_perim,1,cl_emb,">="&$B34,cl_emb,"<="&MIN(EOMONTH($B34,0),DateSit))) -> 1 | E34: =IF($B34>DateSit,"",COUNTIFS(cl_perim,1,cl_sortie,">="&$B34,cl_sortie,"<="&MIN(EOMONTH($B34,0),DateSit))) -> 0 | F34: =IF($B34>DateSit,"",COUNTIFS(cl_perim,1,cl_emb,"<="&MIN(EOMONTH($B34,0),DateSit))-COUNTIFS(cl_perim,1,cl_emb,"<="&MIN(EOMONTH($B34,0),DateSit),cl_sortie,"<="&MIN(EOMONTH($B34,0),DateSit))) -> 27 | G34: =IF($B34>DateSit,"",SUMIFS(INDEX(ab_mois,0,1),ab_perim,1)) -> 26 | H34: =IF($B34>DateSit,"",F34*NETWORKDAYS($B34,MIN(EOMONTH($B34,0),DateSit))) -> 594 | I34: =IF(OR(H34="",H34=0),"",G34/H34) -> 0.043771044
B35: =DATE(YEAR(DateSit),2,1) -> 46054 | C35: =IF($B35>DateSit,"",COUNTIFS(cl_perim,1,cl_emb,"<="&($B35-1))-COUNTIFS(cl_perim,1,cl_emb,"<="&($B35-1),cl_sortie,"<="&($B35-1))) -> 27 | D35: =IF($B35>DateSit,"",COUNTIFS(cl_perim,1,cl_emb,">="&$B35,cl_emb,"<="&MIN(EOMONTH($B35,0),DateSit))) -> 0 | E35: =IF($B35>DateSit,"",COUNTIFS(cl_perim,1,cl_sortie,">="&$B35,cl_sortie,"<="&MIN(EOMONTH($B35,0),DateSit))) -> 0 | F35: =IF($B35>DateSit,"",COUNTIFS(cl_perim,1,cl_emb,"<="&MIN(EOMONTH($B35,0),DateSit))-COUNTIFS(cl_perim,1,cl_emb,"<="&MIN(EOMONTH($B35,0),DateSit),cl_sortie,"<="&MIN(EOMONTH($B35,0),DateSit))) -> 27 | G35: =IF($B35>DateSit,"",SUMIFS(INDEX(ab_mois,0,2),ab_perim,1)) -> 29 | H35: =IF($B35>DateSit,"",F35*NETWORKDAYS($B35,MIN(EOMONTH($B35,0),DateSit))) -> 540 | I35: =IF(OR(H35="",H35=0),"",G35/H35) -> 0.053703704
B36: =DATE(YEAR(DateSit),3,1) -> 46082 | C36: =IF($B36>DateSit,"",COUNTIFS(cl_perim,1,cl_emb,"<="&($B36-1))-COUNTIFS(cl_perim,1,cl_emb,"<="&($B36-1),cl_sortie,"<="&($B36-1))) -> 27 | D36: =IF($B36>DateSit,"",COUNTIFS(cl_perim,1,cl_emb,">="&$B36,cl_emb,"<="&MIN(EOMONTH($B36,0),DateSit))) -> 1 | E36: =IF($B36>DateSit,"",COUNTIFS(cl_perim,1,cl_sortie,">="&$B36,cl_sortie,"<="&MIN(EOMONTH($B36,0),DateSit))) -> 1 | F36: =IF($B36>DateSit,"",COUNTIFS(cl_perim,1,cl_emb,"<="&MIN(EOMONTH($B36,0),DateSit))-COUNTIFS(cl_perim,1,cl_emb,"<="&MIN(EOMONTH($B36,0),DateSit),cl_sortie,"<="&MIN(EOMONTH($B36,0),DateSit))) -> 27 | G36: =IF($B36>DateSit,"",SUMIFS(INDEX(ab_mois,0,3),ab_perim,1)) -> 112 | H36: =IF($B36>DateSit,"",F36*NETWORKDAYS($B36,MIN(EOMONTH($B36,0),DateSit))) -> 594 | I36: =IF(OR(H36="",H36=0),"",G36/H36) -> 0.18855219
B37: =DATE(YEAR(DateSit),4,1) -> 46113 | C37: =IF($B37>DateSit,"",COUNTIFS(cl_perim,1,cl_emb,"<="&($B37-1))-COUNTIFS(cl_perim,1,cl_emb,"<="&($B37-1),cl_sortie,"<="&($B37-1))) -> 27 | D37: =IF($B37>DateSit,"",COUNTIFS(cl_perim,1,cl_emb,">="&$B37,cl_emb,"<="&MIN(EOMONTH($B37,0),DateSit))) -> 2 | E37: =IF($B37>DateSit,"",COUNTIFS(cl_perim,1,cl_sortie,">="&$B37,cl_sortie,"<="&MIN(EOMONTH($B37,0),DateSit))) -> 0 | F37: =IF($B37>DateSit,"",COUNTIFS(cl_perim,1,cl_emb,"<="&MIN(EOMONTH($B37,0),DateSit))-COUNTIFS(cl_perim,1,cl_emb,"<="&MIN(EOMONTH($B37,0),DateSit),cl_sortie,"<="&MIN(EOMONTH($B37,0),DateSit))) -> 29 | G37: =IF($B37>DateSit,"",SUMIFS(INDEX(ab_mois,0,4),ab_perim,1)) -> 73 | H37: =IF($B37>DateSit,"",F37*NETWORKDAYS($B37,MIN(EOMONTH($B37,0),DateSit))) -> 638 | I37: =IF(OR(H37="",H37=0),"",G37/H37) -> 0.11442006
B38: =DATE(YEAR(DateSit),5,1) -> 46143 | C38: =IF($B38>DateSit,"",COUNTIFS(cl_perim,1,cl_emb,"<="&($B38-1))-COUNTIFS(cl_perim,1,cl_emb,"<="&($B38-1),cl_sortie,"<="&($B38-1))) -> 29 | D38: =IF($B38>DateSit,"",COUNTIFS(cl_perim,1,cl_emb,">="&$B38,cl_emb,"<="&MIN(EOMONTH($B38,0),DateSit))) -> 0 | E38: =IF($B38>DateSit,"",COUNTIFS(cl_perim,1,cl_sortie,">="&$B38,cl_sortie,"<="&MIN(EOMONTH($B38,0),DateSit))) -> 0 | F38: =IF($B38>DateSit,"",COUNTIFS(cl_perim,1,cl_emb,"<="&MIN(EOMONTH($B38,0),DateSit))-COUNTIFS(cl_perim,1,cl_emb,"<="&MIN(EOMONTH($B38,0),DateSit),cl_sortie,"<="&MIN(EOMONTH($B38,0),DateSit))) -> 29 | G38: =IF($B38>DateSit,"",SUMIFS(INDEX(ab_mois,0,5),ab_perim,1)) -> 48 | H38: =IF($B38>DateSit,"",F38*NETWORKDAYS($B38,MIN(EOMONTH($B38,0),DateSit))) -> 609 | I38: =IF(OR(H38="",H38=0),"",G38/H38) -> 0.078817734
B39: =DATE(YEAR(DateSit),6,1) -> 46174 | C39: =IF($B39>DateSit,"",COUNTIFS(cl_perim,1,cl_emb,"<="&($B39-1))-COUNTIFS(cl_perim,1,cl_emb,"<="&($B39-1),cl_sortie,"<="&($B39-1))) -> 29 | D39: =IF($B39>DateSit,"",COUNTIFS(cl_perim,1,cl_emb,">="&$B39,cl_emb,"<="&MIN(EOMONTH($B39,0),DateSit))) -> 0 | E39: =IF($B39>DateSit,"",COUNTIFS(cl_perim,1,cl_sortie,">="&$B39,cl_sortie,"<="&MIN(EOMONTH($B39,0),DateSit))) -> 1 | F39: =IF($B39>DateSit,"",COUNTIFS(cl_perim,1,cl_emb,"<="&MIN(EOMONTH($B39,0),DateSit))-COUNTIFS(cl_perim,1,cl_emb,"<="&MIN(EOMONTH($B39,0),DateSit),cl_sortie,"<="&MIN(EOMONTH($B39,0),DateSit))) -> 28 | G39: =IF($B39>DateSit,"",SUMIFS(INDEX(ab_mois,0,6),ab_perim,1)) -> 54 | H39: =IF($B39>DateSit,"",F39*NETWORKDAYS($B39,MIN(EOMONTH($B39,0),DateSit))) -> 616 | I39: =IF(OR(H39="",H39=0),"",G39/H39) -> 0.087662338
B40: =DATE(YEAR(DateSit),7,1) -> 46204 | C40: =IF($B40>DateSit,"",COUNTIFS(cl_perim,1,cl_emb,"<="&($B40-1))-COUNTIFS(cl_perim,1,cl_emb,"<="&($B40-1),cl_sortie,"<="&($B40-1))) -> 28 | D40: =IF($B40>DateSit,"",COUNTIFS(cl_perim,1,cl_emb,">="&$B40,cl_emb,"<="&MIN(EOMONTH($B40,0),DateSit))) -> 0 | E40: =IF($B40>DateSit,"",COUNTIFS(cl_perim,1,cl_sortie,">="&$B40,cl_sortie,"<="&MIN(EOMONTH($B40,0),DateSit))) -> 0 | F40: =IF($B40>DateSit,"",COUNTIFS(cl_perim,1,cl_emb,"<="&MIN(EOMONTH($B40,0),DateSit))-COUNTIFS(cl_perim,1,cl_emb,"<="&MIN(EOMONTH($B40,0),DateSit),cl_sortie,"<="&MIN(EOMONTH($B40,0),DateSit))) -> 28 | G40: =IF($B40>DateSit,"",SUMIFS(INDEX(ab_mois,0,7),ab_perim,1)) -> 61 | H40: =IF($B40>DateSit,"",F40*NETWORKDAYS($B40,MIN(EOMONTH($B40,0),DateSit))) -> 644 | I40: =IF(OR(H40="",H40=0),"",G40/H40) -> 0.094720497
B41: =DATE(YEAR(DateSit),8,1) -> 46235 | C41: =IF($B41>DateSit,"",COUNTIFS(cl_perim,1,cl_emb,"<="&($B41-1))-COUNTIFS(cl_perim,1,cl_emb,"<="&($B41-1),cl_sortie,"<="&($B41-1))) -> 28 | D41: =IF($B41>DateSit,"",COUNTIFS(cl_perim,1,cl_emb,">="&$B41,cl_emb,"<="&MIN(EOMONTH($B41,0),DateSit))) -> 0 | E41: =IF($B41>DateSit,"",COUNTIFS(cl_perim,1,cl_sortie,">="&$B41,cl_sortie,"<="&MIN(EOMONTH($B41,0),DateSit))) -> 0 | F41: =IF($B41>DateSit,"",COUNTIFS(cl_perim,1,cl_emb,"<="&MIN(EOMONTH($B41,0),DateSit))-COUNTIFS(cl_perim,1,cl_emb,"<="&MIN(EOMONTH($B41,0),DateSit),cl_sortie,"<="&MIN(EOMONTH($B41,0),DateSit))) -> 28 | G41: =IF($B41>DateSit,"",SUMIFS(INDEX(ab_mois,0,8),ab_perim,1)) -> 41 | H41: =IF($B41>DateSit,"",F41*NETWORKDAYS($B41,MIN(EOMONTH($B41,0),DateSit))) -> 588 | I41: =IF(OR(H41="",H41=0),"",G41/H41) -> 0.069727891
B42: =DATE(YEAR(DateSit),9,1) -> 46266 | C42: =IF($B42>DateSit,"",COUNTIFS(cl_perim,1,cl_emb,"<="&($B42-1))-COUNTIFS(cl_perim,1,cl_emb,"<="&($B42-1),cl_sortie,"<="&($B42-1))) -> 28 | D42: =IF($B42>DateSit,"",COUNTIFS(cl_perim,1,cl_emb,">="&$B42,cl_emb,"<="&MIN(EOMONTH($B42,0),DateSit))) -> 0 | E42: =IF($B42>DateSit,"",COUNTIFS(cl_perim,1,cl_sortie,">="&$B42,cl_sortie,"<="&MIN(EOMONTH($B42,0),DateSit))) -> 1 | F42: =IF($B42>DateSit,"",COUNTIFS(cl_perim,1,cl_emb,"<="&MIN(EOMONTH($B42,0),DateSit))-COUNTIFS(cl_perim,1,cl_emb,"<="&MIN(EOMONTH($B42,0),DateSit),cl_sortie,"<="&MIN(EOMONTH($B42,0),DateSit))) -> 27 | G42: =IF($B42>DateSit,"",SUMIFS(INDEX(ab_mois,0,9),ab_perim,1)) -> 91 | H42: =IF($B42>DateSit,"",F42*NETWORKDAYS($B42,MIN(EOMONTH($B42,0),DateSit))) -> 594 | I42: =IF(OR(H42="",H42=0),"",G42/H42) -> 0.15319865
B43: =DATE(YEAR(DateSit),10,1) -> 46296 | C43: =IF($B43>DateSit,"",COUNTIFS(cl_perim,1,cl_emb,"<="&($B43-1))-COUNTIFS(cl_perim,1,cl_emb,"<="&($B43-1),cl_sortie,"<="&($B43-1))) -> 27 | D43: =IF($B43>DateSit,"",COUNTIFS(cl_perim,1,cl_emb,">="&$B43,cl_emb,"<="&MIN(EOMONTH($B43,0),DateSit))) -> 0 | E43: =IF($B43>DateSit,"",COUNTIFS(cl_perim,1,cl_sortie,">="&$B43,cl_sortie,"<="&MIN(EOMONTH($B43,0),DateSit))) -> 0 | F43: =IF($B43>DateSit,"",COUNTIFS(cl_perim,1,cl_emb,"<="&MIN(EOMONTH($B43,0),DateSit))-COUNTIFS(cl_perim,1,cl_emb,"<="&MIN(EOMONTH($B43,0),DateSit),cl_sortie,"<="&MIN(EOMONTH($B43,0),DateSit))) -> 27 | G43: =IF($B43>DateSit,"",SUMIFS(INDEX(ab_mois,0,10),ab_perim,1)) -> 97 | H43: =IF($B43>DateSit,"",F43*NETWORKDAYS($B43,MIN(EOMONTH($B43,0),DateSit))) -> 594 | I43: =IF(OR(H43="",H43=0),"",G43/H43) -> 0.16329966
B44: =DATE(YEAR(DateSit),11,1) -> 46327 | C44: =IF($B44>DateSit,"",COUNTIFS(cl_perim,1,cl_emb,"<="&($B44-1))-COUNTIFS(cl_perim,1,cl_emb,"<="&($B44-1),cl_sortie,"<="&($B44-1))) | D44: =IF($B44>DateSit,"",COUNTIFS(cl_perim,1,cl_emb,">="&$B44,cl_emb,"<="&MIN(EOMONTH($B44,0),DateSit))) | E44: =IF($B44>DateSit,"",COUNTIFS(cl_perim,1,cl_sortie,">="&$B44,cl_sortie,"<="&MIN(EOMONTH($B44,0),DateSit))) | F44: =IF($B44>DateSit,"",COUNTIFS(cl_perim,1,cl_emb,"<="&MIN(EOMONTH($B44,0),DateSit))-COUNTIFS(cl_perim,1,cl_emb,"<="&MIN(EOMONTH($B44,0),DateSit),cl_sortie,"<="&MIN(EOMONTH($B44,0),DateSit))) | G44: =IF($B44>DateSit,"",SUMIFS(INDEX(ab_mois,0,11),ab_perim,1)) | H44: =IF($B44>DateSit,"",F44*NETWORKDAYS($B44,MIN(EOMONTH($B44,0),DateSit))) | I44: =IF(OR(H44="",H44=0),"",G44/H44)
B45: =DATE(YEAR(DateSit),12,1) -> 46357 | C45: =IF($B45>DateSit,"",COUNTIFS(cl_perim,1,cl_emb,"<="&($B45-1))-COUNTIFS(cl_perim,1,cl_emb,"<="&($B45-1),cl_sortie,"<="&($B45-1))) | D45: =IF($B45>DateSit,"",COUNTIFS(cl_perim,1,cl_emb,">="&$B45,cl_emb,"<="&MIN(EOMONTH($B45,0),DateSit))) | E45: =IF($B45>DateSit,"",COUNTIFS(cl_perim,1,cl_sortie,">="&$B45,cl_sortie,"<="&MIN(EOMONTH($B45,0),DateSit))) | F45: =IF($B45>DateSit,"",COUNTIFS(cl_perim,1,cl_emb,"<="&MIN(EOMONTH($B45,0),DateSit))-COUNTIFS(cl_perim,1,cl_emb,"<="&MIN(EOMONTH($B45,0),DateSit),cl_sortie,"<="&MIN(EOMONTH($B45,0),DateSit))) | G45: =IF($B45>DateSit,"",SUMIFS(INDEX(ab_mois,0,12),ab_perim,1)) | H45: =IF($B45>DateSit,"",F45*NETWORKDAYS($B45,MIN(EOMONTH($B45,0),DateSit))) | I45: =IF(OR(H45="",H45=0),"",G45/H45)
B46: Total année | D46: =SUM(D34:D45) -> 4 | E46: =SUM(E34:E45) -> 3 | G46: =SUM(G34:G45) -> 632 | H46: =SUM(H34:H45) -> 6011 | I46: =IF(H46=0,"",G46/H46) -> 0.10514058
...

Sheet Paramètres
A1: Paramètres et listes de référence
A2: Données fictives – Portfolio personnel, non officiel de Nuru
A3: Paramètre | B3: Valeur | C3: Commentaire | E3: Départements | F3: Bureaux | G3: Catégories d'absence | H3: Statuts des stages | I3: Niveaux d'alerte des contrats
A4: Seuil « Urgent » (jours) | B4: 30 | C4: Seuil d'alerte interne au projet (repris de analysis/suivi_rh.py), pas une règle juridique. | E4: Tous | F4: Tous | G4: Congé annuel | H4: En cours | I4: Échu, à régulariser
A5: Seuil « À préparer » (jours) | B5: 60 | C5: Seuil d'alerte interne au projet (repris de analysis/suivi_rh.py), pas une règle juridique. | E5: Commercial et service client | F5: Beni | G5: Congé de circonstance | H5: À venir | I5: Urgent (≤ 30 jours)
A6: Seuil « À surveiller » (jours) | B6: 90 | C6: Seuil d'alerte interne au projet (repris de analysis/suivi_rh.py), pas une règle juridique. | E6: Direction | F6: Bukavu | G6: Absence non justifiée | H6: Terminé | I6: À préparer (31 à 60 jours)
E7: Finance | F7: Goma | G7: Absence justifiée (motif confidentiel) | I7: À surveiller (61 à 90 jours)
E8: Informatique | I8: RAS (> 90 jours)
E9: Logistique | I9: Sans échéance (CDI)
E10: Opérations techniques
E11: Ressources humaines
E12: Services généraux

Sheet Contrats
A1: Contrats de travail (sans rémunération)
A2: Données fictives – Portfolio personnel, non officiel de Nuru
A3: Contrat | B3: Matricule | C3: Type | D3: Durée (mois) | E3: Début | F3: Fin | G3: Motif | H3: Clé (calcul)
A4: CTR-0001 | B4: EMP-001 | C4: CDI | E4: 42795 | G4: Embauche initiale | H4: =B4&"|"&E4 -> EMP-001|42795
A5: CTR-0002 | B5: EMP-002 | C5: CDD | D5: 12 | E5: 44348 | F5: 44712 | G5: Embauche initiale | H5: =B5&"|"&E5 -> EMP-002|44348
A6: CTR-0003 | B6: EMP-002 | C6: CDD | D6: 12 | E6: 44713 | F6: 45077 | G6: Renouvellement | H6: =B6&"|"&E6 -> EMP-002|44713
A7: CTR-0004 | B7: EMP-002 | C7: CDI | E7: 45078 | G7: Passage en CDI | H7: =B7&"|"&E7 -> EMP-002|45078
A8: CTR-0005 | B8: EMP-003 | C8: CDD | D8: 12 | E8: 43497 | F8: 43861 | G8: Embauche initiale | H8: =B8&"|"&E8 -> EMP-003|43497
A9: CTR-0006 | B9: EMP-003 | C9: CDI | E9: 43862 | G9: Passage en CDI | H9: =B9&"|"&E9 -> EMP-003|43862
A10: CTR-0007 | B10: EMP-004 | C10: CDD | D10: 12 | E10: 45870 | F10: 46234 | G10: Embauche initiale | H10: =B10&"|"&E10 -> EMP-004|45870
A11: CTR-0008 | B11: EMP-004 | C11: CDD | D11: 12 | E11: 46235 | F11: 46599 | G11: Renouvellement | H11: =B11&"|"&E11 -> EMP-004|46235
A12: CTR-0009 | B12: EMP-005 | C12: CDI | E12: 43346 | G12: Embauche initiale | H12: =B12&"|"&E12 -> EMP-005|43346
A13: CTR-0010 | B13: EMP-006 | C13: CDD | D13: 12 | E13: 44571 | F13: 44935 | G13: Embauche initiale | H13: =B13&"|"&E13 -> EMP-006|44571
A14: CTR-0011 | B14: EMP-006 | C14: CDD | D14: 12 | E14: 44936 | F14: 45300 | G14: Renouvellement | H14: =B14&"|"&E14 -> EMP-006|44936
A15: CTR-0012 | B15: EMP-006 | C15: CDI | E15: 45301 | G15: Passage en CDI | H15: =B15&"|"&E15 -> EMP-006|45301
A16: CTR-0013 | B16: EMP-007 | C16: CDD | D16: 12 | E16: 45992 | F16: 46356 | G16: Embauche initiale | H16: =B16&"|"&E16 -> EMP-007|45992
A17: CTR-0014 | B17: EMP-008 | C17: CDI | E17: 42492 | G17: Embauche initiale | H17: =B17&"|"&E17 -> EMP-008|42492
A18: CTR-0015 | B18: EMP-009 | C18: CDD | D18: 12 | E18: 45600 | F18: 45964 | G18: Embauche initiale | H18: =B18&"|"&E18 -> EMP-009|45600
A19: CTR-0016 | B19: EMP-009 | C19: CDD | D19: 12 | E19: 45965 | F19: 46329 | G19: Renouvellement | H19: =B19&"|"&E19 -> EMP-009|45965
A20: CTR-0017 | B20: EMP-010 | C20: CDI | E20: 42583 | G20: Embauche initiale | H20: =B20&"|"&E20 -> EMP-010|42583
A21: CTR-0018 | B21: EMP-011 | C21: CDD | D21: 12 | E21: 43922 | F21: 44286 | G21: Embauche initiale | H21: =B21&"|"&E21 -> EMP-011|43922
A22: CTR-0019 | B22: EMP-011 | C22: CDI | E22: 44287 | G22: Passage en CDI | H22: =B22&"|"&E22 -> EMP-011|44287
A23: CTR-0020 | B23: EMP-012 | C23: CDD | D23: 12 | E23: 44986 | F23: 45351 | G23: Embauche initiale | H23: =B23&"|"&E23 -> EMP-012|44986
A24: CTR-0021 | B24: EMP-012 | C24: CDD | D24: 12 | E24: 45352 | F24: 45716 | G24: Renouvellement | H24: =B24&"|"&E24 -> EMP-012|45352
A25: CTR-0022 | B25: EMP-012 | C25: CDI | E25: 45717 | G25: Passage en CDI | H25: =B25&"|"&E25 -> EMP-012|45717
A26: CTR-0023 | B26: EMP-013 | C26: CDD | D26: 12 | E26: 44470 | F26: 44834 | G26: Embauche initiale | H26: =B26&"|"&E26 -> EMP-013|44470
A27: CTR-0024 | B27: EMP-013 | C27: CDI | E27: 44835 | G27: Passage en CDI | H27: =B27&"|"&E27 -> EMP-013|44835
A28: CTR-0025 | B28: EMP-014 | C28: CDI | E28: 43647 | G28: Embauche initiale | H28: =B28&"|"&E28 -> EMP-014|43647
A29: CTR-0026 | B29: EMP-015 | C29: CDD | D29: 12 | E29: 43836 | F29: 44201 | G29: Embauche initiale | H29: =B29&"|"&E29 -> EMP-015|43836
A30: CTR-0027 | B30: EMP-015 | C30: CDI | E30: 44202 | G30: Passage en CDI | H30: =B30&"|"&E30 -> EMP-015|44202
A31: CTR-0028 | B31: EMP-016 | C31: CDD | D31: 12 | E31: 46027 | F31: 46391 | G31: Embauche initiale | H31: =B31&"|"&E31 -> EMP-016|46027
A32: CTR-0029 | B32: EMP-017 | C32: CDD | D32: 12 | E32: 44683 | F32: 45047 | G32: Embauche initiale | H32: =B32&"|"&E32 -> EMP-017|44683
A33: CTR-0030 | B33: EMP-017 | C33: CDD | D33: 12 | E33: 45048 | F33: 45413 | G33: Renouvellement | H33: =B33&"|"&E33 -> EMP-017|45048
A34: CTR-0031 | B34: EMP-017 | C34: CDI | E34: 45414 | G34: Passage en CDI | H34: =B34&"|"&E34 -> EMP-017|45414
A35: CTR-0032 | B35: EMP-018 | C35: CDD | D35: 12 | E35: 45323 | F35: 45688 | G35: Embauche initiale | H35: =B35&"|"&E35 -> EMP-018|45323
A36: CTR-0033 | B36: EMP-018 | C36: CDD | D36: 12 | E36: 45689 | F36: 46053 | G36: Renouvellement | H36: =B36&"|"&E36 -> EMP-018|45689
A37: CTR-0034 | B37: EMP-018 | C37: CDI | E37: 46054 | G37: Passage en CDI | H37: =B37&"|"&E37 -> EMP-018|46054
A38: CTR-0035 | B38: EMP-019 | C38: CDD | D38: 12 | E38: 45170 | F38: 45535 | G38: Embauche initiale | H38: =B38&"|"&E38 -> EMP-019|45170
A39: CTR-0036 | B39: EMP-019 | C39: CDD | D39: 12 | E39: 45536 | F39: 45900 | G39: Renouvellement | H39: =B39&"|"&E39 -> EMP-019|45536
A40: CTR-0037 | B40: EMP-019 | C40: CDI | E40: 45901 | G40: Passage en CDI | H40: =B40&"|"&E40 -> EMP-019|45901
...

Sheet Collaborateurs
A1: Registre du personnel et échéances des contrats
A2: Données fictives – Portfolio personnel, non officiel de Nuru
A3: Matricule | B3: Nom | C3: Poste | D3: Département | E3: Bureau | F3: Date d'embauche | G3: Date de sortie | H3: Dans le filtre (1/0) | I3: En poste à la date (1/0) | J3: Début du contrat en vigueur | K3: Type de contrat | L3: Fin du contrat | M3: Jours restants | N3: Niveau d'alerte
A4: EMP-001 | B4: Bienvenu Mukeba | C4: Directeur(trice) pays | D4: Direction | E4: Goma | F4: 42795 | H4: =IF(AND(OR(FiltreDep="Tous",D4=FiltreDep),OR(FiltreBur="Tous",E4=FiltreBur)),1,0) -> 1 | I4: =IF(AND(F4<=DateSit,OR(G4="",G4>DateSit)),1,0) -> 1 | J4: =SUMPRODUCT(MAX((ct_mat=A4)*(ct_deb<=DateSit)*ct_deb)) -> 42795 | K4: =IF(I4=0,"",INDEX(ct_type,MATCH(A4&"|"&J4,ct_cle,0))) -> CDI | L4: =IF(I4=0,"",IF(INDEX(ct_fin,MATCH(A4&"|"&J4,ct_cle,0))="","",INDEX(ct_fin,MATCH(A4&"|"&J4,ct_cle,0)))) | M4: =IF(OR(I4=0,L4=""),"",L4-DateSit) | N4: =IF(I4=0,"",IF(L4="",NivSans,IF(M4<0,NivEchu,IF(M4<=SeuilUrgent,NivUrgent,IF(M4<=SeuilPreparer,NivPreparer,IF(M4<=SeuilSurveiller,NivSurveiller,NivRas)))))) -> Sans échéance (CDI)
A5: EMP-002 | B5: Clarisse Bisimwa | C5: Assistant(e) de direction | D5: Direction | E5: Goma | F5: 44348 | H5: =IF(AND(OR(FiltreDep="Tous",D5=FiltreDep),OR(FiltreBur="Tous",E5=FiltreBur)),1,0) -> 1 | I5: =IF(AND(F5<=DateSit,OR(G5="",G5>DateSit)),1,0) -> 1 | J5: =SUMPRODUCT(MAX((ct_mat=A5)*(ct_deb<=DateSit)*ct_deb)) -> 45078 | K5: =IF(I5=0,"",INDEX(ct_type,MATCH(A5&"|"&J5,ct_cle,0))) -> CDI | L5: =IF(I5=0,"",IF(INDEX(ct_fin,MATCH(A5&"|"&J5,ct_cle,0))="","",INDEX(ct_fin,MATCH(A5&"|"&J5,ct_cle,0)))) | M5: =IF(OR(I5=0,L5=""),"",L5-DateSit) | N5: =IF(I5=0,"",IF(L5="",NivSans,IF(M5<0,NivEchu,IF(M5<=SeuilUrgent,NivUrgent,IF(M5<=SeuilPreparer,NivPreparer,IF(M5<=SeuilSurveiller,NivSurveiller,NivRas)))))) -> Sans échéance (CDI)
A6: EMP-003 | B6: Neema Lukusa | C6: Responsable RH | D6: Ressources humaines | E6: Goma | F6: 43497 | H6: =IF(AND(OR(FiltreDep="Tous",D6=FiltreDep),OR(FiltreBur="Tous",E6=FiltreBur)),1,0) -> 1 | I6: =IF(AND(F6<=DateSit,OR(G6="",G6>DateSit)),1,0) -> 1 | J6: =SUMPRODUCT(MAX((ct_mat=A6)*(ct_deb<=DateSit)*ct_deb)) -> 43862 | K6: =IF(I6=0,"",INDEX(ct_type,MATCH(A6&"|"&J6,ct_cle,0))) -> CDI | L6: =IF(I6=0,"",IF(INDEX(ct_fin,MATCH(A6&"|"&J6,ct_cle,0))="","",INDEX(ct_fin,MATCH(A6&"|"&J6,ct_cle,0)))) | M6: =IF(OR(I6=0,L6=""),"",L6-DateSit) | N6: =IF(I6=0,"",IF(L6="",NivSans,IF(M6<0,NivEchu,IF(M6<=SeuilUrgent,NivUrgent,IF(M6<=SeuilPreparer,NivPreparer,IF(M6<=SeuilSurveiller,NivSurveiller,NivRas)))))) -> Sans échéance (CDI)
A7: EMP-004 | B7: Josué Mirindi | C7: Chargé(e) RH | D7: Ressources humaines | E7: Goma | F7: 45870 | H7: =IF(AND(OR(FiltreDep="Tous",D7=FiltreDep),OR(FiltreBur="Tous",E7=FiltreBur)),1,0) -> 1 | I7: =IF(AND(F7<=DateSit,OR(G7="",G7>DateSit)),1,0) -> 1 | J7: =SUMPRODUCT(MAX((ct_mat=A7)*(ct_deb<=DateSit)*ct_deb)) -> 46235 | K7: =IF(I7=0,"",INDEX(ct_type,MATCH(A7&"|"&J7,ct_cle,0))) -> CDD | L7: =IF(I7=0,"",IF(INDEX(ct_fin,MATCH(A7&"|"&J7,ct_cle,0))="","",INDEX(ct_fin,MATCH(A7&"|"&J7,ct_cle,0)))) -> 46599 | M7: =IF(OR(I7=0,L7=""),"",L7-DateSit) -> 273 | N7: =IF(I7=0,"",IF(L7="",NivSans,IF(M7<0,NivEchu,IF(M7<=SeuilUrgent,NivUrgent,IF(M7<=SeuilPreparer,NivPreparer,IF(M7<=SeuilSurveiller,NivSurveiller,NivRas)))))) -> RAS (> 90 jours)
A8: EMP-005 | B8: Grâce Balume | C8: Responsable financier(ère) | D8: Finance | E8: Goma | F8: 43346 | H8: =IF(AND(OR(FiltreDep="Tous",D8=FiltreDep),OR(FiltreBur="Tous",E8=FiltreBur)),1,0) -> 1 | I8: =IF(AND(F8<=DateSit,OR(G8="",G8>DateSit)),1,0) -> 1 | J8: =SUMPRODUCT(MAX((ct_mat=A8)*(ct_deb<=DateSit)*ct_deb)) -> 43346 | K8: =IF(I8=0,"",INDEX(ct_type,MATCH(A8&"|"&J8,ct_cle,0))) -> CDI | L8: =IF(I8=0,"",IF(INDEX(ct_fin,MATCH(A8&"|"&J8,ct_cle,0))="","",INDEX(ct_fin,MATCH(A8&"|"&J8,ct_cle,0)))) | M8: =IF(OR(I8=0,L8=""),"",L8-DateSit) | N8: =IF(I8=0,"",IF(L8="",NivSans,IF(M8<0,NivEchu,IF(M8<=SeuilUrgent,NivUrgent,IF(M8<=SeuilPreparer,NivPreparer,IF(M8<=SeuilSurveiller,NivSurveiller,NivRas)))))) -> Sans échéance (CDI)
A9: EMP-006 | B9: Patrick Amisi | C9: Comptable | D9: Finance | E9: Goma | F9: 44571 | H9: =IF(AND(OR(FiltreDep="Tous",D9=FiltreDep),OR(FiltreBur="Tous",E9=FiltreBur)),1,0) -> 1 | I9: =IF(AND(F9<=DateSit,OR(G9="",G9>DateSit)),1,0) -> 1 | J9: =SUMPRODUCT(MAX((ct_mat=A9)*(ct_deb<=DateSit)*ct_deb)) -> 45301 | K9: =IF(I9=0,"",INDEX(ct_type,MATCH(A9&"|"&J9,ct_cle,0))) -> CDI | L9: =IF(I9=0,"",IF(INDEX(ct_fin,MATCH(A9&"|"&J9,ct_cle,0))="","",INDEX(ct_fin,MATCH(A9&"|"&J9,ct_cle,0)))) | M9: =IF(OR(I9=0,L9=""),"",L9-DateSit) | N9: =IF(I9=0,"",IF(L9="",NivSans,IF(M9<0,NivEchu,IF(M9<=SeuilUrgent,NivUrgent,IF(M9<=SeuilPreparer,NivPreparer,IF(M9<=SeuilSurveiller,NivSurveiller,NivRas)))))) -> Sans échéance (CDI)
A10: EMP-007 | B10: Rachel Safari | C10: Comptable | D10: Finance | E10: Bukavu | F10: 45992 | H10: =IF(AND(OR(FiltreDep="Tous",D10=FiltreDep),OR(FiltreBur="Tous",E10=FiltreBur)),1,0) -> 1 | I10: =IF(AND(F10<=DateSit,OR(G10="",G10>DateSit)),1,0) -> 1 | J10: =SUMPRODUCT(MAX((ct_mat=A10)*(ct_deb<=DateSit)*ct_deb)) -> 45992 | K10: =IF(I10=0,"",INDEX(ct_type,MATCH(A10&"|"&J10,ct_cle,0))) -> CDD | L10: =IF(I10=0,"",IF(INDEX(ct_fin,MATCH(A10&"|"&J10,ct_cle,0))="","",INDEX(ct_fin,MATCH(A10&"|"&J10,ct_cle,0)))) -> 46356 | M10: =IF(OR(I10=0,L10=""),"",L10-DateSit) -> 30 | N10: =IF(I10=0,"",IF(L10="",NivSans,IF(M10<0,NivEchu,IF(M10<=SeuilUrgent,NivUrgent,IF(M10<=SeuilPreparer,NivPreparer,IF(M10<=SeuilSurveiller,NivSurveiller,NivRas)))))) -> Urgent (≤ 30 jours)
A11: EMP-008 | B11: Olivier Kalume | C11: Responsable logistique | D11: Logistique | E11: Goma | F11: 42492 | H11: =IF(AND(OR(FiltreDep="Tous",D11=FiltreDep),OR(FiltreBur="Tous",E11=FiltreBur)),1,0) -> 1 | I11: =IF(AND(F11<=DateSit,OR(G11="",G11>DateSit)),1,0) -> 1 | J11: =SUMPRODUCT(MAX((ct_mat=A11)*(ct_deb<=DateSit)*ct_deb)) -> 42492 | K11: =IF(I11=0,"",INDEX(ct_type,MATCH(A11&"|"&J11,ct_cle,0))) -> CDI | L11: =IF(I11=0,"",IF(INDEX(ct_fin,MATCH(A11&"|"&J11,ct_cle,0))="","",INDEX(ct_fin,MATCH(A11&"|"&J11,ct_cle,0)))) | M11: =IF(OR(I11=0,L11=""),"",L11-DateSit) | N11: =IF(I11=0,"",IF(L11="",NivSans,IF(M11<0,NivEchu,IF(M11<=SeuilUrgent,NivUrgent,IF(M11<=SeuilPreparer,NivPreparer,IF(M11<=SeuilSurveiller,NivSurveiller,NivRas)))))) -> Sans échéance (CDI)
A12: EMP-009 | B12: Divine Shabani | C12: Logisticien(ne) | D12: Logistique | E12: Goma | F12: 45600 | H12: =IF(AND(OR(FiltreDep="Tous",D12=FiltreDep),OR(FiltreBur="Tous",E12=FiltreBur)),1,0) -> 1 | I12: =IF(AND(F12<=DateSit,OR(G12="",G12>DateSit)),1,0) -> 1 | J12: =SUMPRODUCT(MAX((ct_mat=A12)*(ct_deb<=DateSit)*ct_deb)) -> 45965 | K12: =IF(I12=0,"",INDEX(ct_type,MATCH(A12&"|"&J12,ct_cle,0))) -> CDD | L12: =IF(I12=0,"",IF(INDEX(ct_fin,MATCH(A12&"|"&J12,ct_cle,0))="","",INDEX(ct_fin,MATCH(A12&"|"&J12,ct_cle,0)))) -> 46329 | M12: =IF(OR(I12=0,L12=""),"",L12-DateSit) -> 3 | N12: =IF(I12=0,"",IF(L12="",NivSans,IF(M12<0,NivEchu,IF(M12<=SeuilUrgent,NivUrgent,IF(M12<=SeuilPreparer,NivPreparer,IF(M12<=SeuilSurveiller,NivSurveiller,NivRas)))))) -> Urgent (≤ 30 jours)
A13: EMP-010 | B13: Dieudonné Byamungu | C13: Chauffeur | D13: Logistique | E13: Goma | F13: 42583 | H13: =IF(AND(OR(FiltreDep="Tous",D13=FiltreDep),OR(FiltreBur="Tous",E13=FiltreBur)),1,0) -> 1 | I13: =IF(AND(F13<=DateSit,OR(G13="",G13>DateSit)),1,0) -> 1 | J13: =SUMPRODUCT(MAX((ct_mat=A13)*(ct_deb<=DateSit)*ct_deb)) -> 42583 | K13: =IF(I13=0,"",INDEX(ct_type,MATCH(A13&"|"&J13,ct_cle,0))) -> CDI | L13: =IF(I13=0,"",IF(INDEX(ct_fin,MATCH(A13&"|"&J13,ct_cle,0))="","",INDEX(ct_fin,MATCH(A13&"|"&J13,ct_cle,0)))) | M13: =IF(OR(I13=0,L13=""),"",L13-DateSit) | N13: =IF(I13=0,"",IF(L13="",NivSans,IF(M13<0,NivEchu,IF(M13<=SeuilUrgent,NivUrgent,IF(M13<=SeuilPreparer,NivPreparer,IF(M13<=SeuilSurveiller,NivSurveiller,NivRas)))))) -> Sans échéance (CDI)
A14: EMP-011 | B14: Espoir Cirhuza | C14: Chauffeur | D14: Logistique | E14: Bukavu | F14: 43922 | H14: =IF(AND(OR(FiltreDep="Tous",D14=FiltreDep),OR(FiltreBur="Tous",E14=FiltreBur)),1,0) -> 1 | I14: =IF(AND(F14<=DateSit,OR(G14="",G14>DateSit)),1,0) -> 1 | J14: =SUMPRODUCT(MAX((ct_mat=A14)*(ct_deb<=DateSit)*ct_deb)) -> 44287 | K14: =IF(I14=0,"",INDEX(ct_type,MATCH(A14&"|"&J14,ct_cle,0))) -> CDI | L14: =IF(I14=0,"",IF(INDEX(ct_fin,MATCH(A14&"|"&J14,ct_cle,0))="","",INDEX(ct_fin,MATCH(A14&"|"&J14,ct_cle,0)))) | M14: =IF(OR(I14=0,L14=""),"",L14-DateSit) | N14: =IF(I14=0,"",IF(L14="",NivSans,IF(M14<0,NivEchu,IF(M14<=SeuilUrgent,NivUrgent,IF(M14<=SeuilPreparer,NivPreparer,IF(M14<=SeuilSurveiller,NivSurveiller,NivRas)))))) -> Sans échéance (CDI)
A15: EMP-012 | B15: Héritier Kubuya | C15: Chauffeur | D15: Logistique | E15: Beni | F15: 44986 | H15: =IF(AND(OR(FiltreDep="Tous",D15=FiltreDep),OR(FiltreBur="Tous",E15=FiltreBur)),1,0) -> 1 | I15: =IF(AND(F15<=DateSit,OR(G15="",G15>DateSit)),1,0) -> 1 | J15: =SUMPRODUCT(MAX((ct_mat=A15)*(ct_deb<=DateSit)*ct_deb)) -> 45717 | K15: =IF(I15=0,"",INDEX(ct_type,MATCH(A15&"|"&J15,ct_cle,0))) -> CDI | L15: =IF(I15=0,"",IF(INDEX(ct_fin,MATCH(A15&"|"&J15,ct_cle,0))="","",INDEX(ct_fin,MATCH(A15&"|"&J15,ct_cle,0)))) | M15: =IF(OR(I15=0,L15=""),"",L15-DateSit) | N15: =IF(I15=0,"",IF(L15="",NivSans,IF(M15<0,NivEchu,IF(M15<=SeuilUrgent,NivUrgent,IF(M15<=SeuilPreparer,NivPreparer,IF(M15<=SeuilSurveiller,NivSurveiller,NivRas)))))) -> Sans échéance (CDI)
... A22: EMP-019 | B22: Faraja Maombi | C22: Technicien(ne) électricien(ne) | D22: Opérations techniques | E22: Beni | F22: 45170 | H22: =IF(AND(OR(FiltreDep="Tous",D22=FiltreDep),OR(FiltreBur="Tous",E22=FiltreBur)),1,0) -> 1 | I22: =IF(AND(F22<=DateSit,OR(G22="",G22>DateSit)),1,0) -> 1 | J22: =SUMPRODUCT(MAX((ct_mat=A22)*(ct_deb<=DateSit)*ct_deb)) -> 45901 | K22: =IF(I22=0,"",INDEX(ct_type,MATCH(A22&"|"&J22,ct_cle,0))) -> CDI | L22: =IF(I22=0,"",IF(INDEX(ct_fin,MATCH(A22&"|"&J22,ct_cle,0))="","",INDEX(ct_fin,MATCH(A22&"|"&J22,ct_cle,0)))) | M22: =IF(OR(I22=0,L22=""),"",L22-DateSit) | N22: =IF(I22=0,"",IF(L22="",NivSans,IF(M22<0,NivEchu,IF(M22<=SeuilUrgent,NivUrgent,IF(M22<=SeuilPreparer,NivPreparer,IF(M22<=SeuilSurveiller,NivSurveiller,NivRas)))))) -> Sans échéance (CDI)
A23: EMP-020 | B23: Riziki Barhakomerwa | C23: Technicien(ne) électricien(ne) | D23: Opérations techniques | E23: Bukavu | F23: 46113 | G23: 46295 | H23: =IF(AND(OR(FiltreDep="Tous",D23=FiltreDep),OR(FiltreBur="Tous",E23=FiltreBur)),1,0) -> 1 | I23: =IF(AND(F23<=DateSit,OR(G23="",G23>DateSit)),1,0) -> 0 | J23: =SUMPRODUCT(MAX((ct_mat=A23)*(ct_deb<=DateSit)*ct_deb)) -> 46113 | K23: =IF(I23=0,"",INDEX(ct_type,MATCH(A23&"|"&J23,ct_cle,0))) | L23: =IF(I23=0,"",IF(INDEX(ct_fin,MATCH(A23&"|"&J23,ct_cle,0))="","",INDEX(ct_fin,MATCH(A23&"|"&J23,ct_cle,0)))) | M23: =IF(OR(I23=0,L23=""),"",L23-DateSit) | N23: =IF(I23=0,"",IF(L23="",NivSans,IF(M23<0,NivEchu,IF(M23<=SeuilUrgent,NivUrgent,IF(M23<=SeuilPreparer,NivPreparer,IF(M23<=SeuilSurveiller,NivSurveiller,NivRas))))))
A24: EMP-021 | B24: Imani Lwaboshi | C24: Technicien(ne) électricien(ne) | D24: Opérations techniques | E24: Goma | F24: 45782 | H24: =IF(AND(OR(FiltreDep="Tous",D24=FiltreDep),OR(FiltreBur="Tous",E24=FiltreBur)),1,0) -> 1 | I24: =IF(AND(F24<=DateSit,OR(G24="",G24>DateSit)),1,0) -> 1 | J24: =SUMPRODUCT(MAX((ct_mat=A24)*(ct_deb<=DateSit)*ct_deb)) -> 46147 | K24: =IF(I24=0,"",INDEX(ct_type,MATCH(A24&"|"&J24,ct_cle,0))) -> CDD | L24: =IF(I24=0,"",IF(INDEX(ct_fin,MATCH(A24&"|"&J24,ct_cle,0))="","",INDEX(ct_fin,MATCH(A24&"|"&J24,ct_cle,0)))) -> 46330 | M24: =IF(OR(I24=0,L24=""),"",L24-DateSit) -> 4 | N24: =IF(I24=0,"",IF(L24="",NivSans,IF(M24<0,NivEchu,IF(M24<=SeuilUrgent,NivUrgent,IF(M24<=SeuilPreparer,NivPreparer,IF(M24<=SeuilSurveiller,NivSurveiller,NivRas)))))) -> Urgent (≤ 30 jours)
A25: EMP-022 | B25: Jospin Ilunga | C25: Technicien(ne) électricien(ne) | D25: Opérations techniques | E25: Beni | F25: 44228 | G25: 46203 | H25: =IF(AND(OR(FiltreDep="Tous",D25=FiltreDep),OR(FiltreBur="Tous",E25=FiltreBur)),1,0) -> 1 | I25: =IF(AND(F25<=DateSit,OR(G25="",G25>DateSit)),1,0) -> 0 | J25: =SUMPRODUCT(MAX((ct_mat=A25)*(ct_deb<=DateSit)*ct_deb)) -> 44593 | K25: =IF(I25=0,"",INDEX(ct_type,MATCH(A25&"|"&J25,ct_cle,0))) | L25: =IF(I25=0,"",IF(INDEX(ct_fin,MATCH(A25&"|"&J25,ct_cle,0))="","",INDEX(ct_fin,MATCH(A25&"|"&J25,ct_cle,0)))) | M25: =IF(OR(I25=0,L25=""),"",L25-DateSit) | N25: =IF(I25=0,"",IF(L25="",NivSans,IF(M25<0,NivEchu,IF(M25<=SeuilUrgent,NivUrgent,IF(M25<=SeuilPreparer,NivPreparer,IF(M25<=SeuilSurveiller,NivSurveiller,NivRas))))))
A26: EMP-023 | B26: Furaha Nsimire | C26: Responsable commercial(e) | D26: Commercial et service client | E26: Goma | F26: 43136 | H26: =IF(AND(OR(FiltreDep="Tous",D26=FiltreDep),OR(FiltreBur="Tous",E26=FiltreBur)),1,0) -> 1 | I26: =IF(AND(F26<=DateSit,OR(G26="",G26>DateSit)),1,0) -> 1 | J26: =SUMPRODUCT(MAX((ct_mat=A26)*(ct_deb<=DateSit)*ct_deb)) -> 43136 | K26: =IF(I26=0,"",INDEX(ct_type,MATCH(A26&"|"&J26,ct_cle,0))) -> CDI | L26: =IF(I26=0,"",IF(INDEX(ct_fin,MATCH(A26&"|"&J26,ct_cle,0))="","",INDEX(ct_fin,MATCH(A26&"|"&J26,ct_cle,0)))) | M26: =IF(OR(I26=0,L26=""),"",L26-DateSit) | N26: =IF(I26=0,"",IF(L26="",NivSans,IF(M26<0,NivEchu,IF(M26<=SeuilUrgent,NivUrgent,IF(M26<=SeuilPreparer,NivPreparer,IF(M26<=SeuilSurveiller,NivSurveiller,NivRas)))))) -> Sans échéance (CDI)
A27: EMP-024 | B27: Gloire Kasereka | C27: Agent(e) commercial(e) | D27: Commercial et service client | E27: Goma | F27: 45078 | H27: =IF(AND(OR(FiltreDep="Tous",D27=FiltreDep),OR(FiltreBur="Tous",E27=FiltreBur)),1,0) -> 1 | I27: =IF(AND(F27<=DateSit,OR(G27="",G27>DateSit)),1,0) -> 1 | J27: =SUMPRODUCT(MAX((ct_mat=A27)*(ct_deb<=DateSit)*ct_deb)) -> 45444 | K27: =IF(I27=0,"",INDEX(ct_type,MATCH(A27&"|"&J27,ct_cle,0))) -> CDI | L27: =IF(I27=0,"",IF(INDEX(ct_fin,MATCH(A27&"|"&J27,ct_cle,0))="","",INDEX(ct_fin,MATCH(A27&"|"&J27,ct_cle,0)))) | M27: =IF(OR(I27=0,L27=""),"",L27-DateSit) | N27: =IF(I27=0,"",IF(L27="",NivSans,IF(M27<0,NivEchu,IF(M27<=SeuilUrgent,NivUrgent,IF(M27<=SeuilPreparer,NivPreparer,IF(M27<=SeuilSurveiller,NivSurveiller,NivRas)))))) -> Sans échéance (CDI)
A28: EMP-025 | B28: Zawadi Muhindo | C28: Agent(e) commercial(e) | D28: Commercial et service client | E28: Bukavu | F28: 45474 | H28: =IF(AND(OR(FiltreDep="Tous",D28=FiltreDep),OR(FiltreBur="Tous",E28=FiltreBur)),1,0) -> 1 | I28: =IF(AND(F28<=DateSit,OR(G28="",G28>DateSit)),1,0) -> 1 | J28: =SUMPRODUCT(MAX((ct_mat=A28)*(ct_deb<=DateSit)*ct_deb)) -> 46204 | K28: =IF(I28=0,"",INDEX(ct_type,MATCH(A28&"|"&J28,ct_cle,0))) -> CDI | L28: =IF(I28=0,"",IF(INDEX(ct_fin,MATCH(A28&"|"&J28,ct_cle,0))="","",INDEX(ct_fin,MATCH(A28&"|"&J28,ct_cle,0)))) | M28: =IF(OR(I28=0,L28=""),"",L28-DateSit) | N28: =IF(I28=0,"",IF(L28="",NivSans,IF(M28<0,NivEchu,IF(M28<=SeuilUrgent,NivUrgent,IF(M28<=SeuilPreparer,NivPreparer,IF(M28<=SeuilSurveiller,NivSurveiller,NivRas)))))) -> Sans échéance (CDI)
A29: EMP-026 | B29: Pascal Paluku | C29: Agent(e) commercial(e) | D29: Commercial et service client | E29: Beni | F29: 46083 | H29: =IF(AND(OR(FiltreDep="Tous",D29=FiltreDep),OR(FiltreBur="Tous",E29=FiltreBur)),1,0) -> 1 | I29: =IF(AND(F29<=DateSit,OR(G29="",G29>DateSit)),1,0) -> 1 | J29: =SUMPRODUCT(MAX((ct_mat=A29)*(ct_deb<=DateSit)*ct_deb)) -> 46083 | K29: =IF(I29=0,"",INDEX(ct_type,MATCH(A29&"|"&J29,ct_cle,0))) -> CDD | L29: =IF(I29=0,"",IF(INDEX(ct_fin,MATCH(A29&"|"&J29,ct_cle,0))="","",INDEX(ct_fin,MATCH(A29&"|"&J29,ct_cle,0)))) -> 46447 | M29: =IF(OR(I29=0,L29=""),"",L29-DateSit) -> 121 | N29: =IF(I29=0,"",IF(L29="",NivSans,IF(M29<0,NivEchu,IF(M29<=SeuilUrgent,NivUrgent,IF(M29<=SeuilPreparer,NivPreparer,IF(M29<=SeuilSurveiller,NivSurveiller,NivRas)))))) -> RAS (> 90 jours)
A30: EMP-027 | B30: Merveille Kavira | C30: Chargé(e) service client | D30: Commercial et service client | E30: Goma | F30: 44805 | G30: 46096 | H30: =IF(AND(OR(FiltreDep="Tous",D30=FiltreDep),OR(FiltreBur="Tous",E30=FiltreBur)),1,0) -> 1 | I30: =IF(AND(F30<=DateSit,OR(G30="",G30>DateSit)),1,0) -> 0 | J30: =SUMPRODUCT(MAX((ct_mat=A30)*(ct_deb<=DateSit)*ct_deb)) -> 45170 | K30: =IF(I30=0,"",INDEX(ct_type,MATCH(A30&"|"&J30,ct_cle,0))) | L30: =IF(I30=0,"",IF(INDEX(ct_fin,MATCH(A30&"|"&J30,ct_cle,0))="","",INDEX(ct_fin,MATCH(A30&"|"&J30,ct_cle,0)))) | M30: =IF(OR(I30=0,L30=""),"",L30-DateSit) | N30: =IF(I30=0,"",IF(L30="",NivSans,IF(M30<0,NivEchu,IF(M30<=SeuilUrgent,NivUrgent,IF(M30<=SeuilPreparer,NivPreparer,IF(M30<=SeuilSurveiller,NivSurveiller,NivRas))))))
A31: EMP-028 | B31: Christelle Masika | C31: Chargé(e) service client | D31: Commercial et service client | E31: Goma | F31: 46127 | H31: =IF(AND(OR(FiltreDep="Tous",D31=FiltreDep),OR(FiltreBur="Tous",E31=FiltreBur)),1,0) -> 1 | I31: =IF(AND(F31<=DateSit,OR(G31="",G31>DateSit)),1,0) -> 1 | J31: =SUMPRODUCT(MAX((ct_mat=A31)*(ct_deb<=DateSit)*ct_deb)) -> 46127 | K31: =IF(I31=0,"",INDEX(ct_type,MATCH(A31&"|"&J31,ct_cle,0))) -> CDD | L31: =IF(I31=0,"",IF(INDEX(ct_fin,MATCH(A31&"|"&J31,ct_cle,0))="","",INDEX(ct_fin,MATCH(A31&"|"&J31,ct_cle,0)))) -> 46491 | M31: =IF(OR(I31=0,L31=""),"",L31-DateSit) -> 165 | N31: =IF(I31=0,"",IF(L31="",NivSans,IF(M31<0,NivEchu,IF(M31<=SeuilUrgent,NivUrgent,IF(M31<=SeuilPreparer,NivPreparer,IF(M31<=SeuilSurveiller,NivSurveiller,NivRas)))))) -> RAS (> 90 jours)
A32: EMP-029 | B32: Nadine Mapendo | C32: Administrateur(trice) systèmes | D32: Informatique | E32: Goma | F32: 44105 | H32: =IF(AND(OR(FiltreDep="Tous",D32=FiltreDep),OR(FiltreBur="Tous",E32=FiltreBur)),1,0) -> 1 | I32: =IF(AND(F32<=DateSit,OR(G32="",G32>DateSit)),1,0) -> 1 | J32: =SUMPRODUCT(MAX((ct_mat=A32)*(ct_deb<=DateSit)*ct_deb)) -> 44470 | K32: =IF(I32=0,"",INDEX(ct_type,MATCH(A32&"|"&J32,ct_cle,0))) -> CDI | L32: =IF(I32=0,"",IF(INDEX(ct_fin,MATCH(A32&"|"&J32,ct_cle,0))="","",INDEX(ct_fin,MATCH(A32&"|"&J32,ct_cle,0)))) | M32: =IF(OR(I32=0,L32=""),"",L32-DateSit) | N32: =IF(I32=0,"",IF(L32="",NivSans,IF(M32<0,NivEchu,IF(M32<=SeuilUrgent,NivUrgent,IF(M32<=SeuilPreparer,NivPreparer,IF(M32<=SeuilSurveiller,NivSurveiller,NivRas)))))) -> Sans échéance (CDI)
A33: EMP-030 | B33: Bahati Kambale | C33: Agent(e) de sécurité | D33: Services généraux | E33: Goma | F33: 43773 | H33: =IF(AND(OR(FiltreDep="Tous",D33=FiltreDep),OR(FiltreBur="Tous",E33=FiltreBur)),1,0) -> 1 | I33: =IF(AND(F33<=DateSit,OR(G33="",G33>DateSit)),1,0) -> 1 | J33: =SUMPRODUCT(MAX((ct_mat=A33)*(ct_deb<=DateSit)*ct_deb)) -> 43773 | K33: =IF(I33=0,"",INDEX(ct_type,MATCH(A33&"|"&J33,ct_cle,0))) -> CDI | L33: =IF(I33=0,"",IF(INDEX(ct_fin,MATCH(A33&"|"&J33,ct_cle,0))="","",INDEX(ct_fin,MATCH(A33&"|"&J33,ct_cle,0)))) | M33: =IF(OR(I33=0,L33=""),"",L33-DateSit) | N33: =IF(I33=0,"",IF(L33="",NivSans,IF(M33<0,NivEchu,IF(M33<=SeuilUrgent,NivUrgent,IF(M33<=SeuilPreparer,NivPreparer,IF(M33<=SeuilSurveiller,NivSurveiller,NivRas)))))) -> Sans échéance (CDI)

Sheet Absences
A1: Absences et congés (motifs de santé regroupés, catégorie confidentielle)
A2: Données fictives – Portfolio personnel, non officiel de Nuru
A3: Absence | B3: Matricule | C3: Collaborateur | D3: Catégorie | E3: Début | F3: Fin | G3: Jours ouvrables | H3: Statut | I3: Département | J3: Bureau | K3: Dans le filtre (1/0) | L3: Réalisée (1/0) | M3: Jours 01 | N3: Jours 02 | O3: Jours 03 | P3: Jours 04 | Q3: Jours 05 | R3: Jours 06 | S3: Jours 07 | T3: Jours 08 | U3: Jours 09 | V3: Jours 10 | W3: Jours 11 | X3: Jours 12 | Y3: Jours année
A4: ABS-0001 | B4: EMP-016 | C4: Aline Zihindula | D4: Absence justifiée (motif confidentiel) | E4: 46029 | F4: 46030 | G4: 2 | H4: Approuvée | I4: =INDEX(cl_dep,MATCH(B4,cl_mat,0)) -> Opérations techniques | J4: =INDEX(cl_bur,MATCH(B4,cl_mat,0)) -> Bukavu | K4: =IF(AND(OR(FiltreDep="Tous",I4=FiltreDep),OR(FiltreBur="Tous",J4=FiltreBur)),1,0) -> 1 | L4: =IF(OR(H4="Approuvée",H4="Constatée"),1,0) -> 1 | M4: =IF($L4=0,0,MAX(0,NETWORKDAYS(MAX($E4,DATE(YEAR(DateSit),1,1)),MIN($F4,EOMONTH(DATE(YEAR(DateSit),1,1),0),DateSit)))) -> 2 | N4: =IF($L4=0,0,MAX(0,NETWORKDAYS(MAX($E4,DATE(YEAR(DateSit),2,1)),MIN($F4,EOMONTH(DATE(YEAR(DateSit),2,1),0),DateSit)))) -> 0 | O4: =IF($L4=0,0,MAX(0,NETWORKDAYS(MAX($E4,DATE(YEAR(DateSit),3,1)),MIN($F4,EOMONTH(DATE(YEAR(DateSit),3,1),0),DateSit)))) -> 0 | P4: =IF($L4=0,0,MAX(0,NETWORKDAYS(MAX($E4,DATE(YEAR(DateSit),4,1)),MIN($F4,EOMONTH(DATE(YEAR(DateSit),4,1),0),DateSit)))) -> 0 | Q4: =IF($L4=0,0,MAX(0,NETWORKDAYS(MAX($E4,DATE(YEAR(DateSit),5,1)),MIN($F4,EOMONTH(DATE(YEAR(DateSit),5,1),0),DateSit)))) -> 0 | R4: =IF($L4=0,0,MAX(0,NETWORKDAYS(MAX($E4,DATE(YEAR(DateSit),6,1)),MIN($F4,EOMONTH(DATE(YEAR(DateSit),6,1),0),DateSit)))) -> 0 | S4: =IF($L4=0,0,MAX(0,NETWORKDAYS(MAX($E4,DATE(YEAR(DateSit),7,1)),MIN($F4,EOMONTH(DATE(YEAR(DateSit),7,1),0),DateSit)))) -> 0 | T4: =IF($L4=0,0,MAX(0,NETWORKDAYS(MAX($E4,DATE(YEAR(DateSit),8,1)),MIN($F4,EOMONTH(DATE(YEAR(DateSit),8,1),0),DateSit)))) -> 0 | U4: =IF($L4=0,0,MAX(0,NETWORKDAYS(MAX($E4,DATE(YEAR(DateSit),9,1)),MIN($F4,EOMONTH(DATE(YEAR(DateSit),9,1),0),DateSit)))) -> 0 | V4: =IF($L4=0,0,MAX(0,NETWORKDAYS(MAX($E4,DATE(YEAR(DateSit),10,1)),MIN($F4,EOMONTH(DATE(YEAR(DateSit),10,1),0),DateSit)))) -> 0 | W4: =IF($L4=0,0,MAX(0,NETWORKDAYS(MAX($E4,DATE(YEAR(DateSit),11,1)),MIN($F4,EOMONTH(DATE(YEAR(DateSit),11,1),0),DateSit)))) -> 0 | X4: =IF($L4=0,0,MAX(0,NETWORKDAYS(MAX($E4,DATE(YEAR(DateSit),12,1)),MIN($F4,EOMONTH(DATE(YEAR(DateSit),12,1),0),DateSit)))) -> 0 | Y4: =SUM(M4:X4) -> 2
A5: ABS-0002 | B5: EMP-005 | C5: Grâce Balume | D5: Absence justifiée (motif confidentiel) | E5: 46030 | F5: 46035 | G5: 4 | H5: Approuvée | I5: =INDEX(cl_dep,MATCH(B5,cl_mat,0)) -> Finance | J5: =INDEX(cl_bur,MATCH(B5,cl_mat,0)) -> Goma | K5: =IF(AND(OR(FiltreDep="Tous",I5=FiltreDep),OR(FiltreBur="Tous",J5=FiltreBur)),1,0) -> 1 | L5: =IF(OR(H5="Approuvée",H5="Constatée"),1,0) -> 1 | M5: =IF($L5=0,0,MAX(0,NETWORKDAYS(MAX($E5,DATE(YEAR(DateSit),1,1)),MIN($F5,EOMONTH(DATE(YEAR(DateSit),1,1),0),DateSit)))) -> 4 | N5: =IF($L5=0,0,MAX(0,NETWORKDAYS(MAX($E5,DATE(YEAR(DateSit),2,1)),MIN($F5,EOMONTH(DATE(YEAR(DateSit),2,1),0),DateSit)))) -> 0 | O5: =IF($L5=0,0,MAX(0,NETWORKDAYS(MAX($E5,DATE(YEAR(DateSit),3,1)),MIN($F5,EOMONTH(DATE(YEAR(DateSit),3,1),0),DateSit)))) -> 0 | P5: =IF($L5=0,0,MAX(0,NETWORKDAYS(MAX($E5,DATE(YEAR(DateSit),4,1)),MIN($F5,EOMONTH(DATE(YEAR(DateSit),4,1),0),DateSit)))) -> 0 | Q5: =IF($L5=0,0,MAX(0,NETWORKDAYS(MAX($E5,DATE(YEAR(DateSit),5,1)),MIN($F5,EOMONTH(DATE(YEAR(DateSit),5,1),0),DateSit)))) -> 0 | R5: =IF($L5=0,0,MAX(0,NETWORKDAYS(MAX($E5,DATE(YEAR(DateSit),6,1)),MIN($F5,EOMONTH(DATE(YEAR(DateSit),6,1),0),DateSit)))) -> 0 | S5: =IF($L5=0,0,MAX(0,NETWORKDAYS(MAX($E5,DATE(YEAR(DateSit),7,1)),MIN($F5,EOMONTH(DATE(YEAR(DateSit),7,1),0),DateSit)))) -> 0 | T5: =IF($L5=0,0,MAX(0,NETWORKDAYS(MAX($E5,DATE(YEAR(DateSit),8,1)),MIN($F5,EOMONTH(DATE(YEAR(DateSit),8,1),0),DateSit)))) -> 0 | U5: =IF($L5=0,0,MAX(0,NETWORKDAYS(MAX($E5,DATE(YEAR(DateSit),9,1)),MIN($F5,EOMONTH(DATE(YEAR(DateSit),9,1),0),DateSit)))) -> 0 | V5: =IF($L5=0,0,MAX(0,NETWORKDAYS(MAX($E5,DATE(YEAR(DateSit),10,1)),MIN($F5,EOMONTH(DATE(YEAR(DateSit),10,1),0),DateSit)))) -> 0 | W5: =IF($L5=0,0,MAX(0,NETWORKDAYS(MAX($E5,DATE(YEAR(DateSit),11,1)),MIN($F5,EOMONTH(DATE(YEAR(DateSit),11,1),0),DateSit)))) -> 0 | X5: =IF($L5=0,0,MAX(0,NETWORKDAYS(MAX($E5,DATE(YEAR(DateSit),12,1)),MIN($F5,EOMONTH(DATE(YEAR(DateSit),12,1),0),DateSit)))) -> 0 | Y5: =SUM(M5:X5) -> 4
A6: ABS-0003 | B6: EMP-008 | C6: Olivier Kalume | D6: Absence justifiée (motif confidentiel) | E6: 46030 | F6: 46035 | G6: 4 | H6: Approuvée | I6: =INDEX(cl_dep,MATCH(B6,cl_mat,0)) -> Logistique | J6: =INDEX(cl_bur,MATCH(B6,cl_mat,0)) -> Goma | K6: =IF(AND(OR(FiltreDep="Tous",I6=FiltreDep),OR(FiltreBur="Tous",J6=FiltreBur)),1,0) -> 1 | L6: =IF(OR(H6="Approuvée",H6="Constatée"),1,0) -> 1 | M6: =IF($L6=0,0,MAX(0,NETWORKDAYS(MAX($E6,DATE(YEAR(DateSit),1,1)),MIN($F6,EOMONTH(DATE(YEAR(DateSit),1,1),0),DateSit)))) -> 4 | N6: =IF($L6=0,0,MAX(0,NETWORKDAYS(MAX($E6,DATE(YEAR(DateSit),2,1)),MIN($F6,EOMONTH(DATE(YEAR(DateSit),2,1),0),DateSit)))) -> 0 | O6: =IF($L6=0,0,MAX(0,NETWORKDAYS(MAX($E6,DATE(YEAR(DateSit),3,1)),MIN($F6,EOMONTH(DATE(YEAR(DateSit),3,1),0),DateSit)))) -> 0 | P6: =IF($L6=0,0,MAX(0,NETWORKDAYS(MAX($E6,DATE(YEAR(DateSit),4,1)),MIN($F6,EOMONTH(DATE(YEAR(DateSit),4,1),0),DateSit)))) -> 0 | Q6: =IF($L6=0,0,MAX(0,NETWORKDAYS(MAX($E6,DATE(YEAR(DateSit),5,1)),MIN($F6,EOMONTH(DATE(YEAR(DateSit),5,1),0),DateSit)))) -> 0 | R6: =IF($L6=0,0,MAX(0,NETWORKDAYS(MAX($E6,DATE(YEAR(DateSit),6,1)),MIN($F6,EOMONTH(DATE(YEAR(DateSit),6,1),0),DateSit)))) -> 0 | S6: =IF($L6=0,0,MAX(0,NETWORKDAYS(MAX($E6,DATE(YEAR(DateSit),7,1)),MIN($F6,EOMONTH(DATE(YEAR(DateSit),7,1),0),DateSit)))) -> 0 | T6: =IF($L6=0,0,MAX(0,NETWORKDAYS(MAX($E6,DATE(YEAR(DateSit),8,1)),MIN($F6,EOMONTH(DATE(YEAR(DateSit),8,1),0),DateSit)))) -> 0 | U6: =IF($L6=0,0,MAX(0,NETWORKDAYS(MAX($E6,DATE(YEAR(DateSit),9,1)),MIN($F6,EOMONTH(DATE(YEAR(DateSit),9,1),0),DateSit)))) -> 0 | V6: =IF($L6=0,0,MAX(0,NETWORKDAYS(MAX($E6,DATE(YEAR(DateSit),10,1)),MIN($F6,EOMONTH(DATE(YEAR(DateSit),10,1),0),DateSit)))) -> 0 | W6: =IF($L6=0,0,MAX(0,NETWORKDAYS(MAX($E6,DATE(YEAR(DateSit),11,1)),MIN($F6,EOMONTH(DATE(YEAR(DateSit),11,1),0),DateSit)))) -> 0 | X6: =IF($L6=0,0,MAX(0,NETWORKDAYS(MAX($E6,DATE(YEAR(DateSit),12,1)),MIN($F6,EOMONTH(DATE(YEAR(DateSit),12,1),0),DateSit)))) -> 0 | Y6: =SUM(M6:X6) -> 4
A7: ABS-0004 | B7: EMP-017 | C7: Baraka Mwamba | D7: Absence justifiée (motif confidentiel) | E7: 46036 | F7: 46037 | G7: 2 | H7: Approuvée | I7: =INDEX(cl_dep,MATCH(B7,cl_mat,0)) -> Opérations techniques | J7: =INDEX(cl_bur,MATCH(B7,cl_mat,0)) -> Goma | K7: =IF(AND(OR(FiltreDep="Tous",I7=FiltreDep),OR(FiltreBur="Tous",J7=FiltreBur)),1,0) -> 1 | L7: =IF(OR(H7="Approuvée",H7="Constatée"),1,0) -> 1 | M7: =IF($L7=0,0,MAX(0,NETWORKDAYS(MAX($E7,DATE(YEAR(DateSit),1,1)),MIN($F7,EOMONTH(DATE(YEAR(DateSit),1,1),0),DateSit)))) -> 2 | N7: =IF($L7=0,0,MAX(0,NETWORKDAYS(MAX($E7,DATE(YEAR(DateSit),2,1)),MIN($F7,EOMONTH(DATE(YEAR(DateSit),2,1),0),DateSit)))) -> 0 | O7: =IF($L7=0,0,MAX(0,NETWORKDAYS(MAX($E7,DATE(YEAR(DateSit),3,1)),MIN($F7,EOMONTH(DATE(YEAR(DateSit),3,1),0),DateSit)))) -> 0 | P7: =IF($L7=0,0,MAX(0,NETWORKDAYS(MAX($E7,DATE(YEAR(DateSit),4,1)),MIN($F7,EOMONTH(DATE(YEAR(DateSit),4,1),0),DateSit)))) -> 0 | Q7: =IF($L7=0,0,MAX(0,NETWORKDAYS(MAX($E7,DATE(YEAR(DateSit),5,1)),MIN($F7,EOMONTH(DATE(YEAR(DateSit),5,1),0),DateSit)))) -> 0 | R7: =IF($L7=0,0,MAX(0,NETWORKDAYS(MAX($E7,DATE(YEAR(DateSit),6,1)),MIN($F7,EOMONTH(DATE(YEAR(DateSit),6,1),0),DateSit)))) -> 0 | S7: =IF($L7=0,0,MAX(0,NETWORKDAYS(MAX($E7,DATE(YEAR(DateSit),7,1)),MIN($F7,EOMONTH(DATE(YEAR(DateSit),7,1),0),DateSit)))) -> 0 | T7: =IF($L7=0,0,MAX(0,NETWORKDAYS(MAX($E7,DATE(YEAR(DateSit),8,1)),MIN($F7,EOMONTH(DATE(YEAR(DateSit),8,1),0),DateSit)))) -> 0 | U7: =IF($L7=0,0,MAX(0,NETWORKDAYS(MAX($E7,DATE(YEAR(DateSit),9,1)),MIN($F7,EOMONTH(DATE(YEAR(DateSit),9,1),0),DateSit)))) -> 0 | V7: =IF($L7=0,0,MAX(0,NETWORKDAYS(MAX($E7,DATE(YEAR(DateSit),10,1)),MIN($F7,EOMONTH(DATE(YEAR(DateSit),10,1),0),DateSit)))) -> 0 | W7: =IF($L7=0,0,MAX(0,NETWORKDAYS(MAX($E7,DATE(YEAR(DateSit),11,1)),MIN($F7,EOMONTH(DATE(YEAR(DateSit),11,1),0),DateSit)))) -> 0 | X7: =IF($L7=0,0,MAX(0,NETWORKDAYS(MAX($E7,DATE(YEAR(DateSit),12,1)),MIN($F7,EOMONTH(DATE(YEAR(DateSit),12,1),0),DateSit)))) -> 0 | Y7: =SUM(M7:X7) -> 2
A8: ABS-0005 | B8: EMP-021 | C8: Imani Lwaboshi | D8: Absence justifiée (motif confidentiel) | E8: 46042 | F8: 46045 | G8: 4 | H8: Approuvée | I8: =INDEX(cl_dep,MATCH(B8,cl_mat,0)) -> Opérations techniques | J8: =INDEX(cl_bur,MATCH(B8,cl_mat,0)) -> Goma | K8: =IF(AND(OR(FiltreDep="Tous",I8=FiltreDep),OR(FiltreBur="Tous",J8=FiltreBur)),1,0) -> 1 | L8: =IF(OR(H8="Approuvée",H8="Constatée"),1,0) -> 1 | M8: =IF($L8=0,0,MAX(0,NETWORKDAYS(MAX($E8,DATE(YEAR(DateSit),1,1)),MIN($F8,EOMONTH(DATE(YEAR(DateSit),1,1),0),DateSit)))) -> 4 | N8: =IF($L8=0,0,MAX(0,NETWORKDAYS(MAX($E8,DATE(YEAR(DateSit),2,1)),MIN($F8,EOMONTH(DATE(YEAR(DateSit),2,1),0),DateSit)))) -> 0 | O8: =IF($L8=0,0,MAX(0,NETWORKDAYS(MAX($E8,DATE(YEAR(DateSit),3,1)),MIN($F8,EOMONTH(DATE(YEAR(DateSit),3,1),0),DateSit)))) -> 0 | P8: =IF($L8=0,0,MAX(0,NETWORKDAYS(MAX($E8,DATE(YEAR(DateSit),4,1)),MIN($F8,EOMONTH(DATE(YEAR(DateSit),4,1),0),DateSit)))) -> 0 | Q8: =IF($L8=0,0,MAX(0,NETWORKDAYS(MAX($E8,DATE(YEAR(DateSit),5,1)),MIN($F8,EOMONTH(DATE(YEAR(DateSit),5,1),0),DateSit)))) -> 0 | R8: =IF($L8=0,0,MAX(0,NETWORKDAYS(MAX($E8,DATE(YEAR(DateSit),6,1)),MIN($F8,EOMONTH(DATE(YEAR(DateSit),6,1),0),DateSit)))) -> 0 | S8: =IF($L8=0,0,MAX(0,NETWORKDAYS(MAX($E8,DATE(YEAR(DateSit),7,1)),MIN($F8,EOMONTH(DATE(YEAR(DateSit),7,1),0),DateSit)))) -> 0 | T8: =IF($L8=0,0,MAX(0,NETWORKDAYS(MAX($E8,DATE(YEAR(DateSit),8,1)),MIN($F8,EOMONTH(DATE(YEAR(DateSit),8,1),0),DateSit)))) -> 0 | U8: =IF($L8=0,0,MAX(0,NETWORKDAYS(MAX($E8,DATE(YEAR(DateSit),9,1)),MIN($F8,EOMONTH(DATE(YEAR(DateSit),9,1),0),DateSit)))) -> 0 | V8: =IF($L8=0,0,MAX(0,NETWORKDAYS(MAX($E8,DATE(YEAR(DateSit),10,1)),MIN($F8,EOMONTH(DATE(YEAR(DateSit),10,1),0),DateSit)))) -> 0 | W8: =IF($L8=0,0,MAX(0,NETWORKDAYS(MAX($E8,DATE(YEAR(DateSit),11,1)),MIN($F8,EOMONTH(DATE(YEAR(DateSit),11,1),0),DateSit)))) -> 0 | X8: =IF($L8=0,0,MAX(0,NETWORKDAYS(MAX($E8,DATE(YEAR(DateSit),12,1)),MIN($F8,EOMONTH(DATE(YEAR(DateSit),12,1),0),DateSit)))) -> 0 | Y8: =SUM(M8:X8) -> 4
A9: ABS-0006 | B9: EMP-006 | C9: Patrick Amisi | D9: Congé annuel | E9: 46045 | F9: 46052 | G9: 6 | H9: Approuvée | I9: =INDEX(cl_dep,MATCH(B9,cl_mat,0)) -> Finance | J9: =INDEX(cl_bur,MATCH(B9,cl_mat,0)) -> Goma | K9: =IF(AND(OR(FiltreDep="Tous",I9=FiltreDep),OR(FiltreBur="Tous",J9=FiltreBur)),1,0) -> 1 | L9: =IF(OR(H9="Approuvée",H9="Constatée"),1,0) -> 1 | M9: =IF($L9=0,0,MAX(0,NETWORKDAYS(MAX($E9,DATE(YEAR(DateSit),1,1)),MIN($F9,EOMONTH(DATE(YEAR(DateSit),1,1),0),DateSit)))) -> 6 | N9: =IF($L9=0,0,MAX(0,NETWORKDAYS(MAX($E9,DATE(YEAR(DateSit),2,1)),MIN($F9,EOMONTH(DATE(YEAR(DateSit),2,1),0),DateSit)))) -> 0 | O9: =IF($L9=0,0,MAX(0,NETWORKDAYS(MAX($E9,DATE(YEAR(DateSit),3,1)),MIN($F9,EOMONTH(DATE(YEAR(DateSit),3,1),0),DateSit)))) -> 0 | P9: =IF($L9=0,0,MAX(0,NETWORKDAYS(MAX($E9,DATE(YEAR(DateSit),4,1)),MIN($F9,EOMONTH(DATE(YEAR(DateSit),4,1),0),DateSit)))) -> 0 | Q9: =IF($L9=0,0,MAX(0,NETWORKDAYS(MAX($E9,DATE(YEAR(DateSit),5,1)),MIN($F9,EOMONTH(DATE(YEAR(DateSit),5,1),0),DateSit)))) -> 0 | R9: =IF($L9=0,0,MAX(0,NETWORKDAYS(MAX($E9,DATE(YEAR(DateSit),6,1)),MIN($F9,EOMONTH(DATE(YEAR(DateSit),6,1),0),DateSit)))) -> 0 | S9: =IF($L9=0,0,MAX(0,NETWORKDAYS(MAX($E9,DATE(YEAR(DateSit),7,1)),MIN($F9,EOMONTH(DATE(YEAR(DateSit),7,1),0),DateSit)))) -> 0 | T9: =IF($L9=0,0,MAX(0,NETWORKDAYS(MAX($E9,DATE(YEAR(DateSit),8,1)),MIN($F9,EOMONTH(DATE(YEAR(DateSit),8,1),0),DateSit)))) -> 0 | U9: =IF($L9=0,0,MAX(0,NETWORKDAYS(MAX($E9,DATE(YEAR(DateSit),9,1)),MIN($F9,EOMONTH(DATE(YEAR(DateSit),9,1),0),DateSit)))) -> 0 | V9: =IF($L9=0,0,MAX(0,NETWORKDAYS(MAX($E9,DATE(YEAR(DateSit),10,1)),MIN($F9,EOMONTH(DATE(YEAR(DateSit),10,1),0),DateSit)))) -> 0 | W9: =IF($L9=0,0,MAX(0,NETWORKDAYS(MAX($E9,DATE(YEAR(DateSit),11,1)),MIN($F9,EOMONTH(DATE(YEAR(DateSit),11,1),0),DateSit)))) -> 0 | X9: =IF($L9=0,0,MAX(0,NETWORKDAYS(MAX($E9,DATE(YEAR(DateSit),12,1)),MIN($F9,EOMONTH(DATE(YEAR(DateSit),12,1),0),DateSit)))) -> 0 | Y9: =SUM(M9:X9) -> 6
A10: ABS-0007 | B10: EMP-009 | C10: Divine Shabani | D10: Congé annuel | E10: 46049 | F10: 46063 | G10: 11 | H10: Approuvée | I10: =INDEX(cl_dep,MATCH(B10,cl_mat,0)) -> Logistique | J10: =INDEX(cl_bur,MATCH(B10,cl_mat,0)) -> Goma | K10: =IF(AND(OR(FiltreDep="Tous",I10=FiltreDep),OR(FiltreBur="Tous",J10=FiltreBur)),1,0) -> 1 | L10: =IF(OR(H10="Approuvée",H10="Constatée"),1,0) -> 1 | M10: =IF($L10=0,0,MAX(0,NETWORKDAYS(MAX($E10,DATE(YEAR(DateSit),1,1)),MIN($F10,EOMONTH(DATE(YEAR(DateSit),1,1),0),DateSit)))) -> 4 | N10: =IF($L10=0,0,MAX(0,NETWORKDAYS(MAX($E10,DATE(YEAR(DateSit),2,1)),MIN($F10,EOMONTH(DATE(YEAR(DateSit),2,1),0),DateSit)))) -> 7 | O10: =IF($L10=0,0,MAX(0,NETWORKDAYS(MAX($E10,DATE(YEAR(DateSit),3,1)),MIN($F10,EOMONTH(DATE(YEAR(DateSit),3,1),0),DateSit)))) -> 0 | P10: =IF($L10=0,0,MAX(0,NETWORKDAYS(MAX($E10,DATE(YEAR(DateSit),4,1)),MIN($F10,EOMONTH(DATE(YEAR(DateSit),4,1),0),DateSit)))) -> 0 | Q10: =IF($L10=0,0,MAX(0,NETWORKDAYS(MAX($E10,DATE(YEAR(DateSit),5,1)),MIN($F10,EOMONTH(DATE(YEAR(DateSit),5,1),0),DateSit)))) -> 0 | R10: =IF($L10=0,0,MAX(0,NETWORKDAYS(MAX($E10,DATE(YEAR(DateSit),6,1)),MIN($F10,EOMONTH(DATE(YEAR(DateSit),6,1),0),DateSit)))) -> 0 | S10: =IF($L10=0,0,MAX(0,NETWORKDAYS(MAX($E10,DATE(YEAR(DateSit),7,1)),MIN($F10,EOMONTH(DATE(YEAR(DateSit),7,1),0),DateSit)))) -> 0 | T10: =IF($L10=0,0,MAX(0,NETWORKDAYS(MAX($E10,DATE(YEAR(DateSit),8,1)),MIN($F10,EOMONTH(DATE(YEAR(DateSit),8,1),0),DateSit)))) -> 0 | U10: =IF($L10=0,0,MAX(0,NETWORKDAYS(MAX($E10,DATE(YEAR(DateSit),9,1)),MIN($F10,EOMONTH(DATE(YEAR(DateSit),9,1),0),DateSit)))) -> 0 | V10: =IF($L10=0,0,MAX(0,NETWORKDAYS(MAX($E10,DATE(YEAR(DateSit),10,1)),MIN($F10,EOMONTH(DATE(YEAR(DateSit),10,1),0),DateSit)))) -> 0 | W10: =IF($L10=0,0,MAX(0,NETWORKDAYS(MAX($E10,DATE(YEAR(DateSit),11,1)),MIN($F10,EOMONTH(DATE(YEAR(DateSit),11,1),0),DateSit)))) -> 0 | X10: =IF($L10=0,0,MAX(0,NETWORKDAYS(MAX($E10,DATE(YEAR(DateSit),12,1)),MIN($F10,EOMONTH(DATE(YEAR(DateSit),12,1),0),DateSit)))) -> 0 | Y10: =SUM(M10:X10) -> 11
A11: ABS-0008 | B11: EMP-019 | C11: Faraja Maombi | D11: Congé annuel | E11: 46055 | F11: 46063 | G11: 7 | H11: Approuvée | I11: =INDEX(cl_dep,MATCH(B11,cl_mat,0)) -> Opérations techniques | J11: =INDEX(cl_bur,MATCH(B11,cl_mat,0)) -> Beni | K11: =IF(AND(OR(FiltreDep="Tous",I11=FiltreDep),OR(FiltreBur="Tous",J11=FiltreBur)),1,0) -> 1 | L11: =IF(OR(H11="Approuvée",H11="Constatée"),1,0) -> 1 | M11: =IF($L11=0,0,MAX(0,NETWORKDAYS(MAX($E11,DATE(YEAR(DateSit),1,1)),MIN($F11,EOMONTH(DATE(YEAR(DateSit),1,1),0),DateSit)))) -> 0 | N11: =IF($L11=0,0,MAX(0,NETWORKDAYS(MAX($E11,DATE(YEAR(DateSit),2,1)),MIN($F11,EOMONTH(DATE(YEAR(DateSit),2,1),0),DateSit)))) -> 7 | O11: =IF($L11=0,0,MAX(0,NETWORKDAYS(MAX($E11,DATE(YEAR(DateSit),3,1)),MIN($F11,EOMONTH(DATE(YEAR(DateSit),3,1),0),DateSit)))) -> 0 | P11: =IF($L11=0,0,MAX(0,NETWORKDAYS(MAX($E11,DATE(YEAR(DateSit),4,1)),MIN($F11,EOMONTH(DATE(YEAR(DateSit),4,1),0),DateSit)))) -> 0 | Q11: =IF($L11=0,0,MAX(0,NETWORKDAYS(MAX($E11,DATE(YEAR(DateSit),5,1)),MIN($F11,EOMONTH(DATE(YEAR(DateSit),5,1),0),DateSit)))) -> 0 | R11: =IF($L11=0,0,MAX(0,NETWORKDAYS(MAX($E11,DATE(YEAR(DateSit),6,1)),MIN($F11,EOMONTH(DATE(YEAR(DateSit),6,1),0),DateSit)))) -> 0 | S11: =IF($L11=0,0,MAX(0,NETWORKDAYS(MAX($E11,DATE(YEAR(DateSit),7,1)),MIN($F11,EOMONTH(DATE(YEAR(DateSit),7,1),0),DateSit)))) -> 0 | T11: =IF($L11=0,0,MAX(0,NETWORKDAYS(MAX($E11,DATE(YEAR(DateSit),8,1)),MIN($F11,EOMONTH(DATE(YEAR(DateSit),8,1),0),DateSit)))) -> 0 | U11: =IF($L11=0,0,MAX(0,NETWORKDAYS(MAX($E11,DATE(YEAR(DateSit),9,1)),MIN($F11,EOMONTH(DATE(YEAR(DateSit),9,1),0),DateSit)))) -> 0 | V11: =IF($L11=0,0,MAX(0,NETWORKDAYS(MAX($E11,DATE(YEAR(DateSit),10,1)),MIN($F11,EOMONTH(DATE(YEAR(DateSit),10,1),0),DateSit)))) -> 0 | W11: =IF($L11=0,0,MAX(0,NETWORKDAYS(MAX($E11,DATE(YEAR(DateSit),11,1)),MIN($F11,EOMONTH(DATE(YEAR(DateSit),11,1),0),DateSit)))) -> 0 | X11: =IF($L11=0,0,MAX(0,NETWORKDAYS(MAX($E11,DATE(YEAR(DateSit),12,1)),MIN($F11,EOMONTH(DATE(YEAR(DateSit),12,1),0),DateSit)))) -> 0 | Y11: =SUM(M11:X11) -> 7
